[2024-10-28T18:03:57.384+0000] {local_task_job_runner.py:123} INFO - ::group::Pre task execution logs
[2024-10-28T18:03:57.423+0000] {taskinstance.py:2612} INFO - Dependencies all met for dep_context=non-requeueable deps ti=<TaskInstance: simple_etl_dag.extract_task scheduled__2024-10-24T00:00:00+00:00 [queued]>
[2024-10-28T18:03:57.447+0000] {taskinstance.py:2612} INFO - Dependencies all met for dep_context=requeueable deps ti=<TaskInstance: simple_etl_dag.extract_task scheduled__2024-10-24T00:00:00+00:00 [queued]>
[2024-10-28T18:03:57.448+0000] {taskinstance.py:2865} INFO - Starting attempt 1 of 1
[2024-10-28T18:03:57.481+0000] {taskinstance.py:2888} INFO - Executing <Task(PythonOperator): extract_task> on 2024-10-24 00:00:00+00:00
[2024-10-28T18:03:57.499+0000] {warnings.py:112} WARNING - /home/***/.local/lib/python3.12/site-packages/***/task/task_runner/standard_task_runner.py:70: DeprecationWarning: This process (pid=71) is multi-threaded, use of fork() may lead to deadlocks in the child.
  pid = os.fork()

[2024-10-28T18:03:57.505+0000] {standard_task_runner.py:72} INFO - Started process 89 to run task
[2024-10-28T18:03:57.509+0000] {standard_task_runner.py:104} INFO - Running: ['***', 'tasks', 'run', 'simple_etl_dag', 'extract_task', 'scheduled__2024-10-24T00:00:00+00:00', '--job-id', '100', '--raw', '--subdir', 'DAGS_FOLDER/etl.py', '--cfg-path', '/tmp/tmpm4p1ldth']
[2024-10-28T18:03:57.514+0000] {standard_task_runner.py:105} INFO - Job 100: Subtask extract_task
[2024-10-28T18:03:57.617+0000] {task_command.py:467} INFO - Running <TaskInstance: simple_etl_dag.extract_task scheduled__2024-10-24T00:00:00+00:00 [running]> on host c315ecb1fc54
[2024-10-28T18:03:57.802+0000] {taskinstance.py:3131} INFO - Exporting env vars: AIRFLOW_CTX_DAG_OWNER='***' AIRFLOW_CTX_DAG_ID='simple_etl_dag' AIRFLOW_CTX_TASK_ID='extract_task' AIRFLOW_CTX_EXECUTION_DATE='2024-10-24T00:00:00+00:00' AIRFLOW_CTX_TRY_NUMBER='1' AIRFLOW_CTX_DAG_RUN_ID='scheduled__2024-10-24T00:00:00+00:00'
[2024-10-28T18:03:57.806+0000] {logging_mixin.py:190} INFO - Task instance is in running state
[2024-10-28T18:03:57.808+0000] {logging_mixin.py:190} INFO -  Previous state of the Task instance: queued
[2024-10-28T18:03:57.809+0000] {logging_mixin.py:190} INFO - Current task name:extract_task state:running start_date:2024-10-28 18:03:57.425511+00:00
[2024-10-28T18:03:57.811+0000] {logging_mixin.py:190} INFO - Dag name:simple_etl_dag and current dag run status:running
[2024-10-28T18:03:57.812+0000] {taskinstance.py:731} INFO - ::endgroup::
[2024-10-28T18:03:57.815+0000] {taskinstance.py:3310} ERROR - Task failed with exception
Traceback (most recent call last):
  File "/home/airflow/.local/lib/python3.12/site-packages/airflow/models/taskinstance.py", line 767, in _execute_task
    result = _execute_callable(context=context, **execute_callable_kwargs)
             ^^^^^^^^^^^^^^^^^^^^^^^^^^^^^^^^^^^^^^^^^^^^^^^^^^^^^^^^^^^^^
  File "/home/airflow/.local/lib/python3.12/site-packages/airflow/models/taskinstance.py", line 733, in _execute_callable
    return ExecutionCallableRunner(
           ^^^^^^^^^^^^^^^^^^^^^^^^
  File "/home/airflow/.local/lib/python3.12/site-packages/airflow/utils/operator_helpers.py", line 252, in run
    return self.func(*args, **kwargs)
           ^^^^^^^^^^^^^^^^^^^^^^^^^^
  File "/home/airflow/.local/lib/python3.12/site-packages/airflow/models/baseoperator.py", line 406, in wrapper
    return func(self, *args, **kwargs)
           ^^^^^^^^^^^^^^^^^^^^^^^^^^^
  File "/home/airflow/.local/lib/python3.12/site-packages/airflow/operators/python.py", line 238, in execute
    return_value = self.execute_callable()
                   ^^^^^^^^^^^^^^^^^^^^^^^
  File "/home/airflow/.local/lib/python3.12/site-packages/airflow/operators/python.py", line 256, in execute_callable
    return runner.run(*self.op_args, **self.op_kwargs)
           ^^^^^^^^^^^^^^^^^^^^^^^^^^^^^^^^^^^^^^^^^^^
  File "/home/airflow/.local/lib/python3.12/site-packages/airflow/utils/operator_helpers.py", line 252, in run
    return self.func(*args, **kwargs)
           ^^^^^^^^^^^^^^^^^^^^^^^^^^
  File "/opt/airflow/dags/etl.py", line 14, in extract
    raise FileNotFoundError(f"Source file does not exist: {SOURCE_FILE}")
FileNotFoundError: Source file does not exist: /opt/***/source/input_data.csv
[2024-10-28T18:03:57.848+0000] {logging_mixin.py:190} INFO - Task instance in failure state
[2024-10-28T18:03:57.849+0000] {logging_mixin.py:190} INFO - Task start:2024-10-28 18:03:57.425511+00:00 end:2024-10-28 18:03:57.847353+00:00 duration:0.421842
[2024-10-28T18:03:57.850+0000] {logging_mixin.py:190} INFO - Task:<Task(PythonOperator): extract_task> dag:<DAG: simple_etl_dag> dagrun:<DagRun simple_etl_dag @ 2024-10-24 00:00:00+00:00: scheduled__2024-10-24T00:00:00+00:00, state:running, queued_at: 2024-10-28 18:03:50.028883+00:00. externally triggered: False>
[2024-10-28T18:03:57.851+0000] {logging_mixin.py:190} INFO - Failure caused by Source file does not exist: /opt/***/source/input_data.csv
[2024-10-28T18:03:57.853+0000] {taskinstance.py:1225} INFO - Marking task as FAILED. dag_id=simple_etl_dag, task_id=extract_task, run_id=scheduled__2024-10-24T00:00:00+00:00, execution_date=20241024T000000, start_date=20241028T180357, end_date=20241028T180357
[2024-10-28T18:03:57.885+0000] {taskinstance.py:340} INFO - ::group::Post task execution logs
[2024-10-28T18:03:57.887+0000] {standard_task_runner.py:124} ERROR - Failed to execute job 100 for task extract_task (Source file does not exist: /opt/***/source/input_data.csv; 89)
Traceback (most recent call last):
  File "/home/airflow/.local/lib/python3.12/site-packages/airflow/task/task_runner/standard_task_runner.py", line 117, in _start_by_fork
    ret = args.func(args, dag=self.dag)
          ^^^^^^^^^^^^^^^^^^^^^^^^^^^^^
  File "/home/airflow/.local/lib/python3.12/site-packages/airflow/cli/cli_config.py", line 49, in command
    return func(*args, **kwargs)
           ^^^^^^^^^^^^^^^^^^^^^
  File "/home/airflow/.local/lib/python3.12/site-packages/airflow/utils/cli.py", line 115, in wrapper
    return f(*args, **kwargs)
           ^^^^^^^^^^^^^^^^^^
  File "/home/airflow/.local/lib/python3.12/site-packages/airflow/cli/commands/task_command.py", line 483, in task_run
    task_return_code = _run_task_by_selected_method(args, _dag, ti)
                       ^^^^^^^^^^^^^^^^^^^^^^^^^^^^^^^^^^^^^^^^^^^^
  File "/home/airflow/.local/lib/python3.12/site-packages/airflow/cli/commands/task_command.py", line 256, in _run_task_by_selected_method
    return _run_raw_task(args, ti)
           ^^^^^^^^^^^^^^^^^^^^^^^
  File "/home/airflow/.local/lib/python3.12/site-packages/airflow/cli/commands/task_command.py", line 341, in _run_raw_task
    return ti._run_raw_task(
           ^^^^^^^^^^^^^^^^^
  File "/home/airflow/.local/lib/python3.12/site-packages/airflow/utils/session.py", line 97, in wrapper
    return func(*args, session=session, **kwargs)
           ^^^^^^^^^^^^^^^^^^^^^^^^^^^^^^^^^^^^^^
  File "/home/airflow/.local/lib/python3.12/site-packages/airflow/models/taskinstance.py", line 3004, in _run_raw_task
    return _run_raw_task(
           ^^^^^^^^^^^^^^
  File "/home/airflow/.local/lib/python3.12/site-packages/airflow/models/taskinstance.py", line 273, in _run_raw_task
    TaskInstance._execute_task_with_callbacks(
  File "/home/airflow/.local/lib/python3.12/site-packages/airflow/models/taskinstance.py", line 3158, in _execute_task_with_callbacks
    result = self._execute_task(context, task_orig)
             ^^^^^^^^^^^^^^^^^^^^^^^^^^^^^^^^^^^^^^
  File "/home/airflow/.local/lib/python3.12/site-packages/airflow/models/taskinstance.py", line 3182, in _execute_task
    return _execute_task(self, context, task_orig)
           ^^^^^^^^^^^^^^^^^^^^^^^^^^^^^^^^^^^^^^^
  File "/home/airflow/.local/lib/python3.12/site-packages/airflow/models/taskinstance.py", line 767, in _execute_task
    result = _execute_callable(context=context, **execute_callable_kwargs)
             ^^^^^^^^^^^^^^^^^^^^^^^^^^^^^^^^^^^^^^^^^^^^^^^^^^^^^^^^^^^^^
  File "/home/airflow/.local/lib/python3.12/site-packages/airflow/models/taskinstance.py", line 733, in _execute_callable
    return ExecutionCallableRunner(
           ^^^^^^^^^^^^^^^^^^^^^^^^
  File "/home/airflow/.local/lib/python3.12/site-packages/airflow/utils/operator_helpers.py", line 252, in run
    return self.func(*args, **kwargs)
           ^^^^^^^^^^^^^^^^^^^^^^^^^^
  File "/home/airflow/.local/lib/python3.12/site-packages/airflow/models/baseoperator.py", line 406, in wrapper
    return func(self, *args, **kwargs)
           ^^^^^^^^^^^^^^^^^^^^^^^^^^^
  File "/home/airflow/.local/lib/python3.12/site-packages/airflow/operators/python.py", line 238, in execute
    return_value = self.execute_callable()
                   ^^^^^^^^^^^^^^^^^^^^^^^
  File "/home/airflow/.local/lib/python3.12/site-packages/airflow/operators/python.py", line 256, in execute_callable
    return runner.run(*self.op_args, **self.op_kwargs)
           ^^^^^^^^^^^^^^^^^^^^^^^^^^^^^^^^^^^^^^^^^^^
  File "/home/airflow/.local/lib/python3.12/site-packages/airflow/utils/operator_helpers.py", line 252, in run
    return self.func(*args, **kwargs)
           ^^^^^^^^^^^^^^^^^^^^^^^^^^
  File "/opt/airflow/dags/etl.py", line 14, in extract
    raise FileNotFoundError(f"Source file does not exist: {SOURCE_FILE}")
FileNotFoundError: Source file does not exist: /opt/***/source/input_data.csv
[2024-10-28T18:03:57.929+0000] {local_task_job_runner.py:266} INFO - Task exited with return code 1
[2024-10-28T18:03:57.981+0000] {taskinstance.py:3900} INFO - 0 downstream tasks scheduled from follow-on schedule check
[2024-10-28T18:03:57.992+0000] {local_task_job_runner.py:245} INFO - ::endgroup::
